<?xml version="1.0"?>
<robot xmlns:xacro="http://www.ros.org/wiki/xacro">

    <xacro:include filename="inertial_macros.xacro"/>

    <material name="white">
        <color rgba="1 1 1 1" />
    </material>
    <material name="orange">
        <color rgba="1 0.3 0.1 1"/>
    </material>
    <material name="blue">
        <color rgba="0.2 0.2 1 1"/>
    </material>
    <material name="black">
        <color rgba="0 0 0 1"/>
    </material>

    <!-- BASE LINK -->
    <link name="base_link">
        <visual>
            <origin xyz="0 0 0"/>
            <geometry>
                <box size="0.001 0.001 0.001"/>
            </geometry>
            <material name="black"/>
        </visual>
        <collision>
            <origin xyz="0 0 0"/>
            <geometry>
                <box size="0.001 0.001 0.001"/>
            </geometry>
        </collision>
        <inertial>
            <mass value="1.0"/>
            <origin xyz="0 0 0" rpy="0 0 0"/>
            <inertia ixx="0.01" ixy="0.0" ixz="0.0" iyy="0.01" iyz="0.0" izz="0.01"/>
        </inertial>


    </link>

    <!-- PLUGIN CORRIGIDO PARA GAZEBO HARMONIC -->
    <gazebo>
        <plugin name="gz::sim::systems::DiffDrive" filename="gz-sim-diff-drive-system">
            <topic>/cmd_vel</topic>
            <left_joint>left_wheel_joint</left_joint>
            <right_joint>right_wheel_joint</right_joint>
            <wheel_separation>0.35</wheel_separation>
            <wheel_radius>0.05</wheel_radius>
            <odom_topic>/odom</odom_topic>
            <frame_id>odom</frame_id>
            <child_frame_id>base_link</child_frame_id>
            <odom_publish_frequency>30</odom_publish_frequency>
        </plugin>
    </gazebo>

    <!-- CHASSIS LINK -->
    <joint name="chassis_joint" type="fixed">
        <parent link="base_link"/>
        <child link="chassis"/>
        <origin xyz="-0.1 0 0"/>
    </joint>

    <link name="chassis">
        <visual>
            <origin xyz="0.15 0 0.075"/>
            <geometry>
                <box size="0.3 0.3 0.15"/>
            </geometry>
            <material name="white"/>
        </visual>
        <collision>
            <origin xyz="0.15 0 0.075"/>
            <geometry>
                <box size="0.3 0.3 0.15"/>
            </geometry>
        </collision>
        <xacro:inertial_box mass="0.5" x="0.3" y="0.3" z="0.15">
            <origin xyz="0.15 0 0.075" rpy="0 0 0"/>
        </xacro:inertial_box>
    </link>

    <!-- LEFT WHEEL LINK -->
    <joint name="left_wheel_joint" type="continuous">
        <parent link="base_link"/>
        <child link="left_wheel"/>
        <origin xyz="0 0.175 0" rpy="-${pi/2} 0 0"/>
        <axis xyz="0 0 1"/>
    </joint>

    <link name="left_wheel">
        <visual>
            <geometry>
                <cylinder radius="0.05" length="0.04"/>
            </geometry>
            <material name="blue"/>
        </visual>
        <collision>
            <geometry>
                <cylinder radius="0.05" length="0.04"/>
            </geometry>
        </collision>
        <xacro:inertial_cylinder mass="0.1" length="0.04" radius="0.05">
            <origin xyz="0 0 0" rpy="0 0 0"/>
        </xacro:inertial_cylinder>
    </link>

    <!-- RIGHT WHEEL LINK -->
    <joint name="right_wheel_joint" type="continuous">
        <parent link="base_link"/>
        <child link="right_wheel"/>
        <origin xyz="0 -0.175 0" rpy="${pi/2} 0 0"/>
        <axis xyz="0 0 1"/>
    </joint>

    <link name="right_wheel">
        <visual>
            <geometry>
                <cylinder radius="0.05" length="0.04"/>
            </geometry>
            <material name="blue"/>
        </visual>
        <collision>
            <geometry>
                <cylinder radius="0.05" length="0.04"/>
            </geometry>
        </collision>
        <xacro:inertial_cylinder mass="0.1" length="0.04" radius="0.05">
            <origin xyz="0 0 0" rpy="0 0 0"/>
        </xacro:inertial_cylinder>
    </link>

    <!-- CASTER WHEEL LINK -->
    <joint name="caster_wheel_joint" type="fixed">
        <parent link="chassis"/>
        <child link="caster_wheel"/>
        <origin xyz="0.24 0 0"/>
    </joint>

    <link name="caster_wheel">
        <visual>
            <geometry>
                <sphere radius="0.05"/>
            </geometry>
            <material name="black"/>
        </visual>
        <collision>
            <geometry>
                <sphere radius="0.05"/>
            </geometry>
        </collision>
        <xacro:inertial_sphere mass="0.1" radius="0.05">
            <origin xyz="0 0 0" rpy="0 0 0"/>
        </xacro:inertial_sphere>
    </link>

    <!-- STEP 10 - Lidar -->
    <joint type="fixed" name="scan_joint">
        <origin xyz="0.0 0 0.15" rpy="0 0 0"/>
        <child link="scan_link"/>
        <parent link="base_link"/>
        <axis xyz="0 1 0"/>
    </joint>

    <link name="scan_link">
        <inertial>
            <mass value="1e-5"/>
            <origin xyz="0 0 0.05" rpy="0 0 0"/>
            <inertia ixx="1e-6" ixy="0" ixz="0" iyy="1e-6" iyz="0" izz="1e-6"/>
        </inertial>
        <collision name="collision">
            <origin xyz="0 0 0.05" rpy="0 0 0"/>
            <geometry>
                <box size="0.1 0.1 0.1"/>
            </geometry>
        </collision>
        <visual name="scan_link_visual">
            <origin xyz="0 0 0.05" rpy="0 0 0"/>
            <geometry>
                <mesh filename="/home/brunotavares/infinity_ws/src/infinity_bot/meshes/lidar.dae"/>
            </geometry>
        </visual>

    </link>


    <gazebo reference="scan_link">
        <sensor name="gpu_lidar" type="gpu_lidar">
            <update_rate>10</update_rate>
            <topic>scan</topic>
            <gz_frame_id>scan_link</gz_frame_id>
            <lidar>
                <scan>
                    <horizontal>
                        <samples>720</samples>
                        <resolution>1</resolution>
                        <min_angle>-3.14156</min_angle>
                        <max_angle>3.14156</max_angle>
                    </horizontal>
                </scan>
                <range>
                    <min>0.05</min>
                    <max>10.0</max>
                    <resolution>0.01</resolution>
                </range>
                <noise>
                    <type>gaussian</type>
                    <mean>0.0</mean>
                    <stddev>0.01</stddev>
                </noise>
                <frame_id>scan_link</frame_id>
            </lidar>
            <always_on>1</always_on>
            <visualize>true</visualize>
        </sensor>
    </gazebo>


</robot>
